MemoryError

During handling of the above exception, another exception occurred:

Traceback (most recent call last):
  File "/home/dieaigar/Work/venvs/fond/lib/python3.10/site-packages/unified_planning/model/walkers/dag.py", line 101, in walk
    res = self.iter_walk(expression, **kwargs)
  File "/home/dieaigar/Work/venvs/fond/lib/python3.10/site-packages/unified_planning/model/walkers/dag.py", line 93, in iter_walk
    self._process_stack(**kwargs)
MemoryError

During handling of the above exception, another exception occurred:

MemoryError

During handling of the above exception, another exception occurred:

Traceback (most recent call last):
  File "/home/dieaigar/Work/venvs/fond/lib/python3.10/site-packages/unified_planning/model/expression.py", line 479, in FluentExp
    return self.create_node(
MemoryError

During handling of the above exception, another exception occurred:

MemoryError

During handling of the above exception, another exception occurred:

MemoryError

During handling of the above exception, another exception occurred:

MemoryError

During handling of the above exception, another exception occurred:

MemoryError

During handling of the above exception, another exception occurred:

Traceback (most recent call last):
  File "/home/dieaigar/Work/BOAND/planner/planner.py", line 647, in <module>
    main(sys.argv, len(sys.argv))
  File "/home/dieaigar/Work/BOAND/planner/planner.py", line 622, in main
    solution = boand_star(domain_file, problem_file, solution_folder, use_metric=metric, use_cp_heuristic=heuristic, use_best_case_heuristic=best_heuristic, use_worst_case_heuristic=worst_heuristic, use_size_heuristic=size_heuristic, use_selector=selector)
  File "/home/dieaigar/Work/BOAND/planner/planner.py", line 369, in boand_star
    task = get_alloutcome_determinization(domain, problem)
  File "/home/dieaigar/Work/BOAND/planner/preprocessing.py", line 34, in get_alloutcome_determinization
    ncr_result = negative_conditions_remover.compile(
  File "/home/dieaigar/Work/venvs/fond/lib/python3.10/site-packages/unified_planning/engines/mixins/compiler.py", line 93, in compile
    return self._compile(problem, compilation_kind)
MemoryError
real 397.11
user 395.07
sys 3.24
